Workbook

Sheet Income Statement
A1: In $ millions
A2: Fiscal years ended | B2: September 28, 2024 | C2: September 30, 2023 | D2: October 1, 2022 | E2: October 2, 2021
A3: Net sales | B3: 12300 | C3: 12664 | D3: 14495 | E3: 13850
A4: Cost of goods sold | B4: 10152 | C4: 10354 | D4: 12123 | E4: 11352
A5: Selling, general and administrative | B5: 870 | C5: 886 | D5: 850 | E5: 867
A6: Amortization of intangibles | B6: 250 | C6: 243 | D6: 257 | E6: 288
A7: Restructuring and transaction activities | B7: 91 | C7: 102 | D7: 23 | E7: 51
A8: Operating income | B8: 937 | C8: 1079 | D8: 1242 | E8: 1292
A9: Other expense | B9: 28 | C9: 31 | D9: 22 | E9: 51
A10: Interest expense | B10: 288 | C10: 306 | D10: 286 | E10: 336
A11: Income before income taxes | B11: 621 | C11: 742 | D11: 934 | E11: 905
A12: Income tax expense | B12: 117 | C12: 133 | D12: 168 | E12: 172
A13: Net income | B13: 504 | C13: 609 | D13: 766 | E13: 733

Sheet Balance Sheet
A1: In $ millions
A2: Particulars | B2: 2024 | C2: 2023 | D2: 2022 | E2: 2021
A3: Cash and cash equivalents | B3: 865 | C3: 1203 | D3: 1410 | E3: 1091
A4: Accounts receivable | B4: 1580 | C4: 1568 | D4: 1777 | E4: 1600
A5: Inventories | B5: 1502 | C5: 1557 | D5: 1802 | E5: 1750
A6: Prepaid expenses and other current assets | B6: 215 | C6: 205 | D6: 175 | E6: 190
A7: Total current assets | B7: 4162 | C7: 4533 | D7: 5164 | E7: 4631
A8: Property, plant and equipment | B8: 4700 | C8: 4576 | D8: 4342 | E8: 4200
A9: Goodwill and intangible assets | B9: 6600 | C9: 6684 | D9: 6685 | E9: 6600
A10: Right-of-use assets | B10: 630 | C10: 625 | D10: 521 | E10: 490
A11: Other assets | B11: 170 | C11: 169 | D11: 244 | E11: 230
A12: Total assets | B12: 16613 | C12: 16587 | D12: 16956 | E12: 16151
A13: Accounts payable | B13: 1520 | C13: 1528 | D13: 1795 | E13: 1600
A14: Accrued employee costs | B14: 280 | C14: 273 | D14: 253 | E14: 245
... A29: Total liabilities and stockholders’ equity | B29: 16613 | C29: 16587 | D29: 16956 | E29: 16151

Sheet Cash Flow Statement
A1: In $ millions
A2: Cash Flows | B2: September 28, 2024 | C2: September 30, 2023 | D2: October 1, 2022 | E2: October 2, 2021
A3: Net income | B3: 504 | C3: 609 | D3: 766 | E3: 733
A4: Depreciation | B4: 560 | C4: 575 | D4: 562 | E4: 566
A5: Amortization of intangibles | B5: 250 | C5: 243 | D5: 257 | E5: 288
A6: Non-cash interest expense | B6: 5 | C6: -61 | D6: 6 | E6: 5
A7: Share-based compensation expense | B7: 44 | C7: 42 | D7: 39 | E7: 38
A8: Deferred income tax | B8: -89 | C8: -117 | D8: -48 | E8: -52
A9: Other non-cash operating activities, net | B9: 16 | C9: 22 | D9: -22 | E9: -10
A10: Settlement of derivatives | B10: 26 | C10: 36 | D10: 201 | E10: 185
A11: Accounts receivable | B11: -20 | C11: 294 | D11: -86 | E11: -70
A12: Inventories | B12: 30 | C12: 343 | D12: -3 | E12: -10
A13: Prepaid expenses and other assets | B13: -15 | C13: 1 | D13: 11 | E13: 15
A14: Accounts payable and other liabilities | B14: -4 | C14: -372 | D14: -120 | E14: -90
... A29: Cash and cash equivalents at end of period | B29: 494 | C29: 1203 | D29: 1410 | E29: 1091

Sheet DCF
A1: KEY VARIABLES:
A3: Growth rate - | B3: 0.04 | C3: (reducing by 0.25% every year)
A4: Tax rate - | B4: ='DCF Calculation'!B3 -> 0.20259128
A5: Wacc - | B5: ='DCF Calculation'!B21 -> 0.050621898
A6: Total Debt - | B6: ='DCF Calculation'!B36+'DCF Calculation'!B37 -> 10498
A7: Cash - | B7: ='DCF Calculation'!B38 -> -1203
A8: CAPEX - | B8: =D27 -> 689
A11: CONSENSUS FINANCIAL PROJECTIONS
A12: In $ millions
A13: Particulars | B13: 2021 A | C13: 2022 A | D13: 2023 A | E13: 2024 A | F13: 2025 E | G13: 2026 E | H13: 2027 E | I13: 2028 E
A14: Revenue | B14: ='Income Statement'!E3 -> 13850 | C14: ='Income Statement'!D3 -> 14495 | D14: ='Income Statement'!C3 -> 12664 | E14: ='Income Statement'!B3 -> 12300 | F14: =D14*(1+F15) -> 13170.56 | G14: =F14*(1+G15) -> 13664.456 | H14: =G14*(1+H15) -> 14142.712 | I14: =H14*(1+I15) -> 14602.35
A15: Growth YoY | C15: =(C14/B14)-1 -> 0.046570397 | D15: =(D14/C14)-1 -> -0.12631942 | E15: =(E14/D14)-1 -> -0.028742893 | F15: =B3 -> 0.04 | G15: =F15-0.0025 -> 0.0375 | H15: =G15-0.0025 -> 0.035 | I15: =H15-0.0025 -> 0.0325
A16: Cost of goods sold | B16: ='Income Statement'!E4 -> 11352 | C16: ='Income Statement'!D4 -> 12123 | D16: ='Income Statement'!C4 -> 10354 | E16: ='Income Statement'!B4 -> 10152 | F16: =F14*D17 -> 10768.16 | G16: =G14*F17 -> 11201.285 | H16: =H14*G17 -> 11522.617 | I16: =I14*H17 -> 11824.09
A17: % of Revenue | B17: =B16/B14 -> 0.81963899 | C17: =C16/C14 -> 0.83635736 | D17: =D16/D14 -> 0.81759318 | E17: =E16/E14 -> 0.82536585 | F17: =AVERAGE(B17:E17) - 0.005 -> 0.81973885 | G17: =F17-0.005 -> 0.81473885 | H17: =G17-0.005 -> 0.80973885 | I17: =H17-0.005 -> 0.80473885
A18: Gross Profit | B18: =B14-B16 -> 2498 | C18: =C14-C16 -> 2372 | D18: =D14-D16 -> 2310 | E18: =E14-E16 -> 2148 | F18: =F14-F16 -> 2402.4 | G18: =G14-G16 -> 2463.1706 | H18: =H14-H16 -> 2620.0951 | I18: =I14-I16 -> 2778.26
A19: % of Revenue | B19: =B18/B14 -> 0.18036101 | C19: =C18/C14 -> 0.16364264 | D19: =D18/D14 -> 0.18240682 | E19: =E18/E14 -> 0.17463415 | F19: =F18/F14 -> 0.18240682 | G19: =G18/G14 -> 0.18026115 | H19: =H18/H14 -> 0.18526115 | I19: =I18/I14 -> 0.19026115
A20: Selling, general and administrative expenses | B20: ='Income Statement'!E5 -> 867 | C20: ='Income Statement'!D5 -> 850 | D20: ='Income Statement'!C5 -> 886 | E20: ='Income Statement'!B5 -> 870 | F20: =F14*F21 -> 862.45434 | G20: =G14*G21 -> 928.95752 | H20: =H14*H21 -> 996.82781 | I20: =I14*I21 -> 1065.7306
A21: % of Revenue | B21: =B20/B14 -> 0.062599278 | C21: =C20/C14 -> 0.058640911 | D21: =D20/D14 -> 0.069962097 | E21: =E20/E14 -> 0.070731707 | F21: =AVERAGE(B21:E21) -> 0.065483498 | G21: =F21+0.0025 -> 0.067983498 | H21: =G21+0.0025 -> 0.070483498 | I21: =H21+0.0025 -> 0.072983498
A22: Depreciation & Amortization | B22: ='Cash Flow Statement'!E4 -> 566 | C22: ='Cash Flow Statement'!D4 -> 562 | D22: ='Cash Flow Statement'!C4 -> 575 | E22: ='Cash Flow Statement'!B4 -> 560 | F22: =AVERAGE(B22:D22) -> 567.66667 | G22: =AVERAGE(B22:F22) -> 566.13333 | H22: =AVERAGE(B22:G22) -> 566.13333 | I22: =AVERAGE(B22:H22) -> 566.13333
A23: % of Revenue | B23: =B22/B14 -> 0.040866426 | C23: =C22/C14 -> 0.03877199 | D23: =D22/D14 -> 0.045404296 | E23: =E22/E14 -> 0.045528455 | F23: =F22/F14 -> 0.043101179 | G23: =G22/G14 -> 0.041431092 | H23: =H22/H14 -> 0.040030041 | I23: =I22/I14 -> 0.038770015
A24: Total Operating Expenses | B24: =B20+B22 -> 1433 | C24: =C20+C22 -> 1412 | D24: =D20+D22 -> 1461 | E24: =E20+E22 -> 1430 | F24: =F20+F22 -> 1430.121 | G24: =G20+G22 -> 1495.0909 | H24: =H20+H22 -> 1562.9611 | I24: =I20+I22 -> 1631.8639
A25: EBIT | B25: =B18-B24 -> 1065 | C25: =C18-C24 -> 960 | D25: =D18-D24 -> 849 | E25: =E18-E24 -> 718 | F25: =F18-F24 -> 972.27899 | G25: =G18-G24 -> 968.07975 | H25: =H18-H24 -> 1057.134 | I25: =I18-I24 -> 1146.3961
A27: CAPEX | B27: =-'Cash Flow Statement'!E16 -> 650 | C27: =-'Cash Flow Statement'!D16 -> 687 | D27: =-'Cash Flow Statement'!C16 -> 689 | E27: ='Cash Flow Statement'!B16 -> -286 | F27: =F28*F14 -> 413.16448 | G27: =G28*G14 -> 428.65815 | H27: =H28*H14 -> 443.66119 | I27: =I28*I14 -> 458.08018
A28: % of Revenue | B28: =B27/B14 -> 0.046931408 | C28: =C27/C14 -> 0.047395654 | D28: =D27/D14 -> 0.054406191 | E28: =E27/E14 -> -0.023252033 | F28: =AVERAGE(B28:E28) -> 0.031370305 | G28: =AVERAGE(B28:F28) -> 0.031370305 | H28: =AVERAGE(B28:G28) -> 0.031370305 | I28: =AVERAGE(B28:H28) -> 0.031370305
A31: FREE CASH FLOW
A32: DCF
A33: Years | B33: 2025 | C33: 2026 | D33: 2027 | E33: 2028
A34: Year Count | B34: 1 | C34: 2 | D34: 3 | E34: 4
A35: EBIT | B35: =F25 -> 972.27899 | C35: =G25 -> 968.07975 | D35: =H25 -> 1057.134 | E35: =I25 -> 1146.3961
A36: Add: Tax on EBIT | B36: =-B35*'DCF Calculation'!B3 -> -196.97525 | C36: =-C35*'DCF Calculation'!B3 -> -196.12452 | D36: =-D35*'DCF Calculation'!B3 -> -214.16613 | E36: =-E35*'DCF Calculation'!B3 -> -232.24985
A37: Add:D&A | B37: =F22 -> 567.66667 | C37: =G22 -> 566.13333 | D37: =H22 -> 566.13333 | E37: =I22 -> 566.13333
A38: Less: CAPEX | B38: =-F27 -> -413.16448 | C38: =-G27 -> -428.65815 | D38: =-H27 -> -443.66119 | E38: =-I27 -> -458.08018
A39: Less: NWC | B39: ='DCF Calculation'!F19 -> 169.62472 | C39: ='DCF Calculation'!G19 -> 148.43675 | D39: ='DCF Calculation'!H19 -> 106.26729 | E39: ='DCF Calculation'!I19 -> 121.44029
A40: FCF | B40: =B36+B37-B38-B39 -> 614.23119 | C40: =C36+C37-C38-C39 -> 650.23022 | D40: =D36+D37-D38-D39 -> 689.3611 | E40: =E36+E37-E38-E39 -> 670.52337
A41: Discount Rate | B41: =1/(1+'DCF Calculation'!$B$21)^DCF!B34 -> 0.95181721 | C41: =1/(1+'DCF Calculation'!$B$21)^DCF!C34 -> 0.90595599 | D41: =1/(1+'DCF Calculation'!$B$21)^DCF!D34 -> 0.8623045 | E41: =1/(1+'DCF Calculation'!$B$21)^DCF!E34 -> 0.82075626
A42: PV of Free Cash Flow | B42: =B40*B41 -> 584.63581 | C42: =C40*C41 -> 589.07996 | D42: =D40*D41 -> 594.43918 | E42: =E40*E41 -> 550.33625
A44: TERMINAL VALUE
A45: Terminal Value
A46: TV | B46: =E40*(1+B3)/(B5-B3) -> 65651.572
A47: PV OF TV | B47: =B46/(1+'DCF Calculation'!B21)^DCF!E34 -> 53883.939
...

Sheet DCF Calculation
A1: CALCULATIONS:
A3: Tax Rate | B3: =B4/B5 -> 0.20259128
A4: Tax Expense | B4: ='Income Statement'!E12 -> 172
A5: EBIT | B5: =DCF!D25 -> 849
A8: Change in Working Capital | B8: 2021 | C8: =B8+1 -> 2022 | D8: =C8+1 -> 2023 | E8: 2024 | F8: =E8+1 -> 2025 | G8: =F8+1 -> 2026 | H8: =G8+1 -> 2027 | I8: =H8+1 -> 2028
A9: Days Receivables | B9: =('Balance Sheet'!E4/DCF!B14)*365 -> 42.166065 | C9: ='Balance Sheet'!D4/DCF!C14*365 -> 44.746809 | D9: ='Balance Sheet'!C4/DCF!D14*365 -> 45.192672 | E9: ='Balance Sheet'!B4/DCF!E14*365 -> 46.886179 | F9: =AVERAGE(D9:E9) -> 46.039426 | G9: =AVERAGE(E9:F9) -> 46.462802 | H9: =AVERAGE(F9:G9) -> 46.251114 | I9: =AVERAGE(G9:H9) -> 46.356958
A10: Days Payables | B10: ='Balance Sheet'!E13/DCF!B14*365 -> 42.166065 | C10: ='Balance Sheet'!D13/DCF!C14*365 -> 45.200069 | D10: ='Balance Sheet'!C13/DCF!D14*365 -> 44.039798 | E10: ='Balance Sheet'!B13/DCF!E14*365 -> 45.105691 | F10: =AVERAGE(D10:E10) -> 44.572744 | G10: =AVERAGE(E10:F10) -> 44.839218 | H10: =AVERAGE(F10:G10) -> 44.705981 | I10: =AVERAGE(G10:H10) -> 44.772599
A12: Accounts Receivable | B12: =DCF!B14/365*'DCF Calculation'!B9 -> 1600 | C12: =DCF!C14/365*'DCF Calculation'!C9 -> 1777 | D12: =DCF!D14/365*'DCF Calculation'!D9 -> 1568 | E12: =DCF!E14/365*'DCF Calculation'!E9 -> 1580 | F12: =DCF!F14/365*'DCF Calculation'!F9 -> 1661.274 | G12: =DCF!G14/365*'DCF Calculation'!G9 -> 1739.4217 | H12: =DCF!H14/365*'DCF Calculation'!H9 -> 1792.0991 | I12: =DCF!I14/365*'DCF Calculation'!I9 -> 1854.5768
A13: Accounts Payables | B13: =DCF!B14/365*'DCF Calculation'!B10 -> 1600 | C13: =DCF!C14/365*'DCF Calculation'!C10 -> 1795 | D13: =DCF!D14/365*'DCF Calculation'!D10 -> 1528 | E13: =DCF!E14/365*'DCF Calculation'!E10 -> 1520 | F13: =DCF!F14/365*'DCF Calculation'!F10 -> 1608.3507 | G13: =DCF!G14/365*'DCF Calculation'!G10 -> 1678.6398 | H13: =DCF!H14/365*'DCF Calculation'!H10 -> 1732.2296 | I13: =DCF!I14/365*I10 -> 1791.1923
A14: NWC | B14: =B12-B13 -> 0 | C14: =C12-C13 -> -18 | D14: =D12-D13 -> 40 | E14: =E12-E13 -> 60 | F14: =F12-F13 -> 52.923317 | G14: =G12-G13 -> 60.781912 | H14: =H12-H13 -> 59.869499 | I14: =I12-I13 -> 63.384544
A16: Change in NWC | B16: 2021 | C16: =B16+1 -> 2022 | D16: =C16+1 -> 2023 | E16: 2024 | F16: =E16+1 -> 2025 | G16: =F16+1 -> 2026 | H16: =G16+1 -> 2027 | I16: =H16+1 -> 2028
A17: Change in Accounts Receivable | B17: 0 | C17: =C12-B12 -> 177 | D17: =D12-C12 -> -209 | E17: =E12-D12 -> 12 | F17: =F12-E12 -> 81.274016 | G17: =G12-F12 -> 78.147672 | H17: =H12-G12 -> 52.677438 | I17: =I12-H12 -> 62.47767
A18: Change in Accounts Payables | B18: 0 | C18: =C13-B13 -> 195 | D18: =D13-C13 -> -267 | E18: =E13-D13 -> -8 | F18: =F13-E13 -> 88.350699 | G18: =G13-F13 -> 70.289076 | H18: =H13-G13 -> 53.589851 | I18: =I13-H13 -> 58.962625
A19: NWC | B19: =B17-B18 -> 0 | C19: =SUM(C17:C18) -> 372 | D19: =SUM(D17:D18) -> -476 | E19: =SUM(E17:E18) -> 4 | F19: =SUM(F17:F18) -> 169.62472 | G19: =SUM(G17:G18) -> 148.43675 | H19: =SUM(H17:H18) -> 106.26729 | I19: =SUM(I17:I18) -> 121.44029
A21: WACC | B21: =(B22/(B23+B22))*B27+(B23/(B23+B22))*B30*(1-B3) -> 0.050621898
A22: Equity | B22: ='Balance Sheet'!C28 -> 3216
A23: Debt | B23: ='Balance Sheet'!C18+'Balance Sheet'!C16 -> 8980
A24: Beta | B24: 1.28
A25: Risk Free Rate | B25: 0.0425
A26: Market Risk Premium | B26: 0.0575
A27: Cost of Equity | B27: =B25+B24*(B26) -> 0.1161
A28: Share Price | B28: 67.58
A29: No of Shares outstanding | B29: 115.8
A30: Cost of Debt | B30: =B31/B32 -> 0.034075724
A31: Interest Expense | B31: ='Income Statement'!C10 -> 306
A32: Total Debt | B32: =B23 -> 8980
A35: NET DEBT
A36: Long term | B36: ='Balance Sheet'!C18 -> 8970
A37: Add: Short Term Debt | B37: ='Balance Sheet'!C13 -> 1528
A38: Less: Cash | B38: =-'Balance Sheet'!C3 -> -1203
A39: Net Debt | B39: =SUM(B36:B38) -> 9295

Sheet Ratios
A1: RATIOS:
A2: In $ millions
A3: Particulars | B3: 2021A | C3: 2022A | D3: 2023A | E3: 2024E | F3: 2025E | G3: 2026E | H3: 2027E | I3: 2028E
A4: Revenue ($M) | B4: 13850 | C4: 14495 | D4: 12664 | E4: 12300 | F4: 13170.56 | G4: 13664.456 | H4: 14142.712 | I4: 14602.35
A5: Growth YoY (%) | C5: 0.046570397 | D5: -0.12631942 | E5: -0.028742893 | F5: 0.04 | G5: 0.0375 | H5: 0.035 | I5: 0.0325
A6: Cost of Goods Sold (COGS) ($M) | B6: 11352 | C6: 12123 | D6: 10354 | E6: 10152 | F6: 10768.16 | G6: 11201.285 | H6: 11522.617 | I6: 11824.09
A7: COGS (% of Revenue) | B7: 0.81963899 | C7: 0.83635736 | D7: 0.81759318 | E7: 0.82536585 | F7: 0.81973885 | G7: 0.81473885 | H7: 0.80973885 | I7: 0.80473885
A8: Gross Profit ($M) | B8: 2498 | C8: 2372 | D8: 2310 | E8: 2148 | F8: 2402.4 | G8: 2463.1706 | H8: 2620.0951 | I8: 2778.26
A9: Gross Profit Margin (% of Revenue) | B9: 0.18036101 | C9: 0.16364264 | D9: 0.18240682 | E9: 0.17463415 | F9: 0.18240682 | G9: 0.18026115 | H9: 0.18526115 | I9: 0.19026115
A10: SG&A Expenses ($M) | B10: 867 | C10: 850 | D10: 886 | E10: 870 | F10: 862.45434 | G10: 928.95752 | H10: 996.82781 | I10: 1065.7306
A11: SG&A (% of Revenue) | B11: 0.062599278 | C11: 0.058640911 | D11: 0.069962097 | E11: 0.070731707 | F11: 0.065483498 | G11: 0.067983498 | H11: 0.070483498 | I11: 0.072983498
A12: Depreciation & Amortization ($M) | B12: 566 | C12: 562 | D12: 575 | E12: 560 | F12: 567.66667 | G12: 566.13333 | H12: 566.13333 | I12: 566.13333
A13: Depreciation & Amortization (% Revenue) | B13: 0.040866426 | C13: 0.03877199 | D13: 0.045404296 | E13: 0.045528455 | F13: 0.043101179 | G13: 0.041431092 | H13: 0.040030041 | I13: 0.038770015
A14: Total Operating Expenses ($M) | B14: 1433 | C14: 1412 | D14: 1461 | E14: 1430 | F14: 1430.121 | G14: 1495.0909 | H14: 1562.9611 | I14: 1631.8639
A15: EBIT ($M) | B15: 1065 | C15: 960 | D15: 849 | E15: 718 | F15: 972.27899 | G15: 968.07975 | H15: 1057.134 | I15: 1146.3961
A16: CAPEX ($M) | B16: 650 | C16: 687 | D16: 689 | E16: -286 | F16: 413.16448 | G16: 428.65815 | H16: 443.66119 | I16: 458.08018
A17: CAPEX (% of Revenue) | B17: 0.046931408 | C17: 0.047395654 | D17: 0.054406191 | E17: -0.023252033 | F17: 0.031370305 | G17: 0.031370305 | H17: 0.031370305 | I17: 0.031370305
A20: Financial Ratios (2021A – 2028E)
A22: Ratios | B22: 2021A | C22: 2022A | D22: 2023A | E22: 2024E | F22: 2025E | G22: 2026E | H22: 2027E | I22: 2028E | K22: NOTES
A23: Gross Profit Margin (%) | B23: =B8/B4 -> 0.18036101 | C23: =C8/C4 -> 0.16364264 | D23: =D8/D4 -> 0.18240682 | E23: =E8/E4 -> 0.17463415 | F23: =F8/F4 -> 0.18240682 | G23: =G8/G4 -> 0.18026115 | H23: =H8/H4 -> 0.18526115 | I23: =I8/I4 -> 0.19026115 | K23: 1) Gross Profit Margin improves steadily from 18.04% in 2021 to 19.03% by 2028,
A24: EBIT Margin (%) | B24: =B15/B4 -> 0.076895307 | C24: =C15/C4 -> 0.066229734 | D24: =D15/D4 -> 0.06704043 | E24: =E15/E4 -> 0.058373984 | F24: =F15/F4 -> 0.073822145 | G24: =G15/G4 -> 0.070846563 | H24: =H15/H4 -> 0.074747615 | I24: =I15/I4 -> 0.07850764 | K24: indicating better pricing power or cost control over time.
A25: SG&A to Revenue (%) | B25: =B10/B4 -> 0.062599278 | C25: =C10/C4 -> 0.058640911 | D25: =D10/D4 -> 0.069962097 | E25: =E10/E4 -> 0.070731707 | F25: =F10/F4 -> 0.065483498 | G25: =G10/G4 -> 0.067983498 | H25: =H10/H4 -> 0.070483498 | I25: =I10/I4 -> 0.072983498 | K25: 2) EBITDA Margin shows healthy recovery post-2023, increasing from 10.39% (2024E) to 11.73% (2028E).
A26: CAPEX to Revenue (%) | B26: =B16/B4 -> 0.046931408 | C26: =C16/C4 -> 0.047395654 | D26: =D16/D4 -> 0.054406191 | E26: =E16/E4 -> -0.023252033 | F26: =F16/F4 -> 0.031370305 | G26: =G16/G4 -> 0.031370305 | H26: =H16/H4 -> 0.031370305 | I26: =I16/I4 -> 0.031370305 | K26: This reflects improving operational efficiency despite temporary setbacks.
A27: Depreciation to Revenue (%) | B27: =B12/B4 -> 0.040866426 | C27: =C12/C4 -> 0.03877199 | D27: =D12/D4 -> 0.045404296 | E27: =E12/E4 -> 0.045528455 | F27: =F12/F4 -> 0.043101179 | G27: =G12/G4 -> 0.041431092 | H27: =H12/H4 -> 0.040030041 | I27: =I12/I4 -> 0.038770015 | K27: 3) EBIT Margin grows from a low of 5.84% in 2024E to 7.85% by 2028E, suggesting a strong earnings rebound.
A28: Operating Expense Ratio (%) | B28: =B14/B4 -> 0.1034657 | C28: =C14/C4 -> 0.097412901 | D28: =D14/D4 -> 0.11536639 | E28: =E14/E4 -> 0.11626016 | F28: =F14/F4 -> 0.10858468 | G28: =G14/G4 -> 0.10941459 | H28: =H14/H4 -> 0.11051354 | I28: =I14/I4 -> 0.11175351 | K28: 4) SG&A to Revenue (%) remains well-managed, staying around 6–7%, which shows disciplined overhead control.
A29: COGS to Revenue (%) | B29: =B6/B4 -> 0.81963899 | C29: =C6/C4 -> 0.83635736 | D29: =D6/D4 -> 0.81759318 | E29: =E6/E4 -> 0.82536585 | F29: =F6/F4 -> 0.81759318 | G29: =G6/G4 -> 0.81973885 | H29: =H6/H4 -> 0.81473885 | I29: =I6/I4 -> 0.80973885 | K29: 5) CAPEX to Revenue stabilizes at 3.14% after a one-off adjustment in 2024, signaling long-term reinvestment focus.
A30: EBITDA Margin (%) | B30: =(B15+B12)/B4 -> 0.11776173 | C30: =(C15+C12)/C4 -> 0.10500172 | D30: =(D15+D12)/D4 -> 0.11244473 | E30: =(E15+E12)/E4 -> 0.10390244 | F30: =(F15+F12)/F4 -> 0.11692332 | G30: =(G15+G12)/G4 -> 0.11227766 | H30: =(H15+H12)/H4 -> 0.11477766 | I30: =(I15+I12)/I4 -> 0.11727766 | K30: 6) Operating Expense Ratio remains slightly elevated post-2024 (11.63% to 11.18%) but flattens toward 2028,
K31: indicating fixed costs may still be weighing on margins.
K32: 7) COGS to Revenue remains high (~81–83%), which pressures margins. Any improvement in
K33: supply chain or raw material efficiency could drive better profitability.
